<?xml version="1.0" ?>
<!-- =================================================================================== -->
<!-- |    This document was autogenerated by xacro from tool_create.urdf.xacro         | -->
<!-- |    EDITING THIS FILE BY HAND IS NOT RECOMMENDED                                 | -->
<!-- =================================================================================== -->
<robot name="surgical_tool" xmlns:xacro="http://www.ros.org/wiki/xacro">
  <!-- Macros -->
  <!-- Macros -->
  <!-- <xacro:property name="fricCoeff1" value="10.0"/> -->
  <!-- <xacro:property name="fricCoeff2" value="10.0"/> -->
  <!-- <xacro:property name="kpCollision" value="100000000"/> -->
  <!-- <xacro:property name="fricCoeff1" value="10.0"/> -->
  <!-- <xacro:property name="fricCoeff2" value="10.0"/> -->
  <!-- <xacro:property name="kpCollision" value="100000000"/> -->
  <!-- <xacro:property name="fricCoeff1" value="10.0"/> -->
  <!-- <xacro:property name="fricCoeff2" value="10.0"/> -->
  <!-- <xacro:property name="kpCollision" value="100000000"/> -->
  <!--  -->
  <link name="world"/>
  <link name="right_tool_base_link">
    <inertial>
      <origin rpy="0.0 0.0 0.0" xyz="0.0 0.0 0.0"/>
      <mass value="0.1"/>
      <inertia ixx="0.01" ixy="0.0" ixz="0.0" iyy="0.01" iyz="0.0" izz="0.001"/>
    </inertial>
  </link>
  <!-- link 1: tool_yaw -->
  <link name="right_tool_yaw_link">
    <inertial>
      <origin rpy="0 0 0" xyz="0 0 0"/>
      <mass value="0.05"/>
      <inertia ixx="0.01" ixy="0.0" ixz="0.0" iyy="0.01" iyz="0.0" izz="0.005"/>
    </inertial>
  </link>
  <!-- link 2: tool_pitch_link -->
  <link name="right_tool_pitch_link">
    <inertial>
      <origin rpy="0 0 0" xyz="0 0 0"/>
      <mass value="0.05"/>
      <inertia ixx="0.01" ixy="0.0" ixz="0.0" iyy="0.01" iyz="0.0" izz="0.005"/>
    </inertial>
  </link>
  <link name="right_tool_roll_link">
    <inertial>
      <origin rpy="0 0 0" xyz="0 0 0"/>
      <mass value="0.05"/>
      <inertia ixx="0.01" ixy="0.0" ixz="0.0" iyy="0.01" iyz="0.0" izz="0.005"/>
    </inertial>
  </link>
  <!-- link 3: tool_main_link -->
  <link name="right_tool_main_link">
    <visual>
      <origin rpy="0 0 1.5708" xyz="0 0 0"/>
      <geometry>
        <mesh filename="package://surgical_sim/models/meshes/dae/tool/tool_main_.dae"/>
      </geometry>
    </visual>
    <!-- <collision>
        <origin rpy="0 0 1.5708" xyz="0 0 0"/>
        <geometry>
          <mesh filename="package://surgical_sim/models/meshes/dae/tool/tool_main_.dae"/>      
        </geometry>
      </collision> -->
    <inertial>
      <origin rpy="0 0 0" xyz="0 0 0"/>
      <mass value="0.1"/>
      <inertia ixx="0.00133395833333" ixy="0" ixz="0" iyy="0.00133395833333" iyz="0" izz="1.25e-06"/>
    </inertial>
  </link>
  <link name="right_tool_wrist_link">
    <inertial>
      <origin rpy="0 0 0" xyz="0 0 0"/>
      <mass value="0.001"/>
      <inertia ixx="0.0001" ixy="0.0" ixz="0.0" iyy="0.0001" iyz="0.0" izz="0.0001"/>
    </inertial>
  </link>
  <link name="right_tool_tip_link_ee">
    <inertial>
      <origin rpy="0 0 0" xyz="0 0 0"/>
      <mass value="0.001"/>
      <inertia ixx="0.0001" ixy="0.0" ixz="0.0" iyy="0.0001" iyz="0.0" izz="0.0001"/>
    </inertial>
  </link>
  <gazebo reference="right_tool_yaw_link">
    <turnGravityOff>true</turnGravityOff>
    <mu1>0.12</mu1>
    <mu2>0.12</mu2>
    <!-- <kp>${kpCollision}</kp> -->
    <!-- <kd>${kdCollision}</kd> -->
    <!-- <selfCollide>false</selfCollide> -->
    <maxVel>0.01</maxVel>
    <minDepth>0.001</minDepth>
  </gazebo>
  <gazebo reference="right_tool_pitch_link">
    <turnGravityOff>true</turnGravityOff>
    <mu1>0.12</mu1>
    <mu2>0.12</mu2>
    <!-- <kp>${kpCollision}</kp> -->
    <!-- <kd>${kdCollision}</kd> -->
    <!-- <selfCollide>false</selfCollide> -->
    <maxVel>0.01</maxVel>
    <minDepth>0.001</minDepth>
  </gazebo>
  <gazebo reference="right_tool_roll_link">
    <turnGravityOff>true</turnGravityOff>
    <mu1>0.12</mu1>
    <mu2>0.12</mu2>
    <!-- <kp>${kpCollision}</kp> -->
    <!-- <kd>${kdCollision}</kd> -->
    <!-- <selfCollide>false</selfCollide> -->
    <maxVel>0.01</maxVel>
    <minDepth>0.001</minDepth>
  </gazebo>
  <gazebo reference="right_tool_main_link">
    <turnGravityOff>true</turnGravityOff>
    <mu1>0.12</mu1>
    <mu2>0.12</mu2>
    <!-- <kp>${kpCollision}</kp> -->
    <!-- <kd>${kdCollision}</kd> -->
    <!-- <selfCollide>false</selfCollide> -->
    <maxVel>0.01</maxVel>
    <minDepth>0.001</minDepth>
  </gazebo>
  <gazebo reference="right_tool_wrist_link">
    <turnGravityOff>true</turnGravityOff>
    <mu1>0.12</mu1>
    <mu2>0.12</mu2>
    <!-- <kp>${kpCollision}</kp> -->
    <!-- <kd>${kdCollision}</kd> -->
    <!-- <selfCollide>false</selfCollide> -->
    <maxVel>0.01</maxVel>
    <minDepth>0.001</minDepth>
  </gazebo>
  <gazebo reference="right_tool_tip_link_ee">
    <turnGravityOff>true</turnGravityOff>
    <mu1>0.12</mu1>
    <mu2>0.12</mu2>
    <!-- <kp>${kpCollision}</kp> -->
    <!-- <kd>${kdCollision}</kd> -->
    <!-- <selfCollide>false</selfCollide> -->
    <maxVel>0.01</maxVel>
    <minDepth>0.001</minDepth>
  </gazebo>
  <!-- joint 1: tool_yaw -->
  <joint name="right_tool_pitch" type="revolute">
    <!-- <safety_controller k_position="100.0" k_velocity="40.0" soft_lower_limit="-1.5" soft_upper_limit="1.5"/> -->
    <parent link="right_tool_base_link"/>
    <child link="right_tool_pitch_link"/>
    <axis xyz="0 0 1"/>
    <origin rpy="0 -1.57079632679 3.14159265359" xyz="0.0 0.0 0.0"/>
    <limit effort="1000" lower="-1.5707" upper="1.5707" velocity="10"/>
  </joint>
  <!-- joint 2: tool_pitch -->
  <joint name="right_tool_roll" type="revolute">
    <!-- <safety_controller k_position="100.0" k_velocity="40.0" soft_lower_limit="-1.5" soft_upper_limit="1.5"/> -->
    <parent link="right_tool_pitch_link"/>
    <child link="right_tool_roll_link"/>
    <axis xyz="0 0 1"/>
    <origin rpy="-1.57079632679 -1.57079632679 0" xyz="0 0 0"/>
    <limit effort="1000" lower="-1.5707" upper="1.5707" velocity="10"/>
  </joint>
  <!-- joint : tool Roll -->
  <joint name="right_tool_yaw" type="continuous">
    <!-- <safety_controller k_position="100.0" k_velocity="40.0" soft_lower_limit="-1.5" soft_upper_limit="1.5"/> -->
    <parent link="right_tool_roll_link"/>
    <child link="right_tool_yaw_link"/>
    <axis xyz="0 0 1"/>
    <origin rpy="1.57079632679 0 0" xyz="0 0 0"/>
    <limit effort="1000" velocity="10"/>
    <!-- <limit lower="-${1.5 * pi}" upper="${1.5 * pi}" velocity="2" effort="2"/> -->
  </joint>
  <!-- joint 3: insertion -->
  <joint name="right_tool_insertion" type="prismatic">
    <!-- <safety_controller k_position="100.0" k_velocity="40.0" soft_lower_limit="-1.5" soft_upper_limit="1.5"/> -->
    <parent link="right_tool_yaw_link"/>
    <child link="right_tool_main_link"/>
    <axis xyz="0 0 1"/>
    <origin rpy="0 0 0" xyz="0 0 -0.365"/>
    <limit effort="1000" lower="0.0" upper="0.240" velocity="10"/>
  </joint>
  <joint name="right_tool_wrist_fixed" type="fixed">
    <!-- <safety_controller k_position="100.0" k_velocity="40.0" soft_lower_limit="-1.5" soft_upper_limit="1.5"/> -->
    <parent link="right_tool_main_link"/>
    <child link="right_tool_wrist_link"/>
    <axis xyz="0 0 1"/>
    <origin rpy="0 0 0" xyz="0 0 0.365"/>
  </joint>
  <!-- joint 4-1: tool roll shaft joint FIXED-->
  <joint name="right_tool_tip_link_ee" type="fixed">
    <!-- <safety_controller k_position="100.0" k_velocity="40.0" soft_lower_limit="-1.5" soft_upper_limit="1.5"/> -->
    <parent link="right_tool_wrist_link"/>
    <child link="right_tool_tip_link_ee"/>
    <axis xyz="0 0 1"/>
    <origin rpy="0 0 0" xyz="0 0 0.0"/>
  </joint>
  <transmission name="right_tool_pitch_trans">
    <type>transmission_interface/SimpleTransmission</type>
    <joint name="right_tool_pitch">
      <hardwareInterface>hardware_interface/EffortJointInterface</hardwareInterface>
    </joint>
    <actuator name="right_tool_pitch_motor">
      <hardwareInterface>hardware_interface/EffortJointInterface</hardwareInterface>
      <mechanicalReduction>1</mechanicalReduction>
    </actuator>
  </transmission>
  <transmission name="right_tool_roll_trans">
    <type>transmission_interface/SimpleTransmission</type>
    <joint name="right_tool_roll">
      <hardwareInterface>hardware_interface/EffortJointInterface</hardwareInterface>
    </joint>
    <actuator name="right_tool_roll_motor">
      <hardwareInterface>hardware_interface/EffortJointInterface</hardwareInterface>
      <mechanicalReduction>1</mechanicalReduction>
    </actuator>
  </transmission>
  <transmission name="right_tool_yaw_trans">
    <type>transmission_interface/SimpleTransmission</type>
    <joint name="right_tool_yaw">
      <hardwareInterface>hardware_interface/EffortJointInterface</hardwareInterface>
    </joint>
    <actuator name="right_tool_yaw_motor">
      <hardwareInterface>hardware_interface/EffortJointInterface</hardwareInterface>
      <mechanicalReduction>1</mechanicalReduction>
    </actuator>
  </transmission>
  <transmission name="right_tool_insertion_trans">
    <type>transmission_interface/SimpleTransmission</type>
    <joint name="right_tool_insertion">
      <hardwareInterface>hardware_interface/EffortJointInterface</hardwareInterface>
    </joint>
    <actuator name="right_tool_insertion_motor">
      <hardwareInterface>hardware_interface/EffortJointInterface</hardwareInterface>
      <mechanicalReduction>1</mechanicalReduction>
    </actuator>
  </transmission>
  <gazebo reference="right_tool_pitch">
    <!-- <implicitSpringDamper>1</implicitSpringDamper> -->
    <provideFeedback>1</provideFeedback>
  </gazebo>
  <gazebo reference="right_tool_roll">
    <!-- <implicitSpringDamper>1</implicitSpringDamper> -->
    <provideFeedback>1</provideFeedback>
  </gazebo>
  <gazebo reference="right_tool_yaw">
    <!-- <implicitSpringDamper>1</implicitSpringDamper> -->
    <provideFeedback>1</provideFeedback>
  </gazebo>
  <gazebo reference="right_tool_wrist_fixed">
    <!-- <implicitSpringDamper>1</implicitSpringDamper> -->
    <provideFeedback>1</provideFeedback>
  </gazebo>
  <gazebo reference="right_tool_tip_link_ee">
    <!-- <implicitSpringDamper>1</implicitSpringDamper> -->
    <provideFeedback>1</provideFeedback>
  </gazebo>
  <gazebo reference="right_tool_tip_link_ee">
    <sensor name="camera_camera_sensor" type="camera">
      <always_on>true</always_on>
      <update_rate>30.0</update_rate>
      <camera>
        <pose>0 0 0 0 -1.57079632679 3.14159265359</pose>
        <horizontal_fov>1.4835298642</horizontal_fov>
        <image>
          <format>R8G8B8</format>
          <width>1020</width>
          <height>1020</height>
        </image>
        <clip>
          <near>0.01</near>
          <far>100</far>
        </clip>
      </camera>
      <plugin filename="libgazebo_ros_camera.so" name="camera_camera_controller">
        <alwaysOn>true</alwaysOn>
        <updateRate>30.0</updateRate>
        <cameraName>camera</cameraName>
        <imageTopicName>image_raw</imageTopicName>
        <cameraInfoTopicName>camera_info</cameraInfoTopicName>
        <frameName>right_tool_tip_link_ee</frameName>
        <hackBaseline>0.07</hackBaseline>
        <distortionK1>0.0</distortionK1>
        <distortionK2>0.0</distortionK2>
        <distortionK3>0.0</distortionK3>
        <distortionT1>0.0</distortionT1>
        <distortionT2>0.0</distortionT2>
      </plugin>
    </sensor>
  </gazebo>
  <joint name="world_fixed" type="fixed">
    <parent link="world"/>
    <child link="right_tool_base_link"/>
    <origin rpy="0 0 0" xyz="0.015 0.515 1.3"/>
  </joint>
  <gazebo reference="right_tool_base_link">
    <turnGravityOff>true</turnGravityOff>
    <mu1>0.12</mu1>
    <mu2>0.12</mu2>
    <!-- <kp>${kpCollision}</kp> -->
    <!-- <kd>${kdCollision}</kd> -->
    <!-- <selfCollide>false</selfCollide> -->
    <maxVel>0.01</maxVel>
    <minDepth>0.001</minDepth>
  </gazebo>
  <gazebo>
    <plugin filename="libgazebo_ros_control.so" name="gazebo_ros_control">
      <robotNamespace>/right_tool</robotNamespace>
      <robotParam>/right_tool/robot_description</robotParam>
      <robotSimType>gazebo_ros_control/DefaultRobotHWSim</robotSimType>
      <legacyModeNS>false</legacyModeNS>
    </plugin>
  </gazebo>
</robot>

