<?xml version="1.0" ?>
<!-- =================================================================================== -->
<!-- |    This document was autogenerated by xacro from tool_create.urdf.xacro         | -->
<!-- |    EDITING THIS FILE BY HAND IS NOT RECOMMENDED                                 | -->
<!-- =================================================================================== -->
<robot name="surgical_tool" xmlns:xacro="http://www.ros.org/wiki/xacro">
  <!--  -->
  <link name="world"/>
  <link name="right_tool_base_link">
    <inertial>
      <origin rpy="0.0 0.0 0.0" xyz="0.0 0.0 0.0"/>
      <mass value="0.001"/>
      <inertia ixx="0.001" ixy="0.0" ixz="0.0" iyy="0.0001" iyz="0.0" izz="0.0001"/>
    </inertial>
  </link>
  <!-- link 1: tool_yaw -->
  <link name="right_tool_yaw_link">
    <inertial>
      <origin rpy="0 0 0" xyz="0 0 0"/>
      <mass value="0.05"/>
      <inertia ixx="0.01" ixy="0.0" ixz="0.0" iyy="0.01" iyz="0.0" izz="0.005"/>
    </inertial>
  </link>
  <!-- link 2: tool_pitch_link -->
  <link name="right_tool_pitch_link">
    <inertial>
      <origin rpy="0 0 0" xyz="0 0 0"/>
      <mass value="0.05"/>
      <inertia ixx="0.01" ixy="0.0" ixz="0.0" iyy="0.01" iyz="0.0" izz="0.005"/>
    </inertial>
  </link>
  <link name="right_tool_roll_link">
    <inertial>
      <origin rpy="0 0 0" xyz="0 0 0"/>
      <mass value="0.151"/>
      <inertia ixx="0.01" ixy="0.0" ixz="0.0" iyy="0.01" iyz="0.0" izz="0.005"/>
    </inertial>
  </link>
  <!-- link 3: tool_main_link -->
  <link name="right_tool_main_link">
    <visual>
      <origin rpy="0 0 1.5708" xyz="0 0 0"/>
      <geometry>
        <mesh filename="package://surgical_sim/models/meshes/dae/tool/tool_main_.dae"/>
      </geometry>
    </visual>
    <!-- <collision>
        <origin rpy="0 0 1.5708" xyz="0 0 0"/>
        <geometry>
          <mesh filename="package://surgical_sim/models/meshes/dae/tool/tool_main_.dae"/>      
        </geometry>
      </collision> -->
    <inertial>
      <origin rpy="0 0 0" xyz="0 0 0"/>
      <mass value="0.05"/>
      <inertia ixx="0.01" ixy="0.0" ixz="0.0" iyy="0.01" iyz="0.0" izz="0.005"/>
    </inertial>
  </link>
  <!-- link 4: tool_wrist_link -->
  <link name="right_tool_wrist_link">
    <visual>
      <origin rpy="0 0 1.5708" xyz="0 0 -0.0091"/>
      <geometry>
        <mesh filename="package://surgical_sim/models/meshes/dae/tool/tool_wrist_link.dae"/>
      </geometry>
    </visual>
    <collision>
      <origin rpy="0 0 1.5708" xyz="0 0 -0.0091"/>
      <geometry>
        <mesh filename="package://surgical_sim/models/meshes/dae/tool/tool_wrist_link.dae"/>
      </geometry>
    </collision>
    <inertial>
      <origin rpy="0 0 0" xyz="0 0 0"/>
      <mass value="0.05"/>
      <inertia ixx="0.01" ixy="0.0" ixz="0.0" iyy="0.01" iyz="0.0" izz="0.005"/>
    </inertial>
  </link>
  <!-- link 4-1: tool_wrist_shaft_link -->
  <link name="right_tool_wrist_shaft_link">
    <visual>
      <origin rpy="1.5708 0 0" xyz="0 0.00401 0"/>
      <geometry>
        <mesh filename="package://surgical_sim/models/meshes/dae/tool/tool_wrist_shaft_link.dae"/>
      </geometry>
    </visual>
    <collision>
      <origin rpy="1.5708 0 0" xyz="0 0.00401 0"/>
      <geometry>
        <mesh filename="package://surgical_sim/models/meshes/dae/tool/tool_wrist_shaft_link.dae"/>
      </geometry>
    </collision>
    <inertial>
      <origin rpy="0 0 0" xyz="0 0 0"/>
      <mass value="0.05"/>
      <inertia ixx="0.01" ixy="0.0" ixz="0.0" iyy="0.01" iyz="0.0" izz="0.005"/>
    </inertial>
  </link>
  <gazebo reference="tool_yaw_link">
    <turnGravityOff>true</turnGravityOff>
    <mu1>0.112</mu1>
    <mu2>0.112</mu2>
    <kp>1000000</kp>
    <kd>1</kd>
    <selfCollide>true</selfCollide>
    <maxVel>0.01</maxVel>
    <minDepth>0.003</minDepth>
  </gazebo>
  <gazebo reference="tool_pitch_link">
    <turnGravityOff>true</turnGravityOff>
    <mu1>0.112</mu1>
    <mu2>0.112</mu2>
    <kp>1000000</kp>
    <kd>1</kd>
    <selfCollide>true</selfCollide>
    <maxVel>0.01</maxVel>
    <minDepth>0.003</minDepth>
  </gazebo>
  <gazebo reference="tool_roll_link">
    <turnGravityOff>true</turnGravityOff>
    <mu1>0.112</mu1>
    <mu2>0.112</mu2>
    <kp>1000000</kp>
    <kd>1</kd>
    <selfCollide>true</selfCollide>
    <maxVel>0.01</maxVel>
    <minDepth>0.003</minDepth>
  </gazebo>
  <gazebo reference="tool_main_link">
    <turnGravityOff>true</turnGravityOff>
    <mu1>0.112</mu1>
    <mu2>0.112</mu2>
    <kp>1000000</kp>
    <kd>1</kd>
    <selfCollide>true</selfCollide>
    <maxVel>0.01</maxVel>
    <minDepth>0.003</minDepth>
  </gazebo>
  <gazebo reference="tool_wrist_link">
    <turnGravityOff>true</turnGravityOff>
    <mu1>0.112</mu1>
    <mu2>0.112</mu2>
    <kp>1000000</kp>
    <kd>1</kd>
    <selfCollide>true</selfCollide>
    <maxVel>0.01</maxVel>
    <minDepth>0.003</minDepth>
  </gazebo>
  <gazebo reference="tool_wrist_shaft_link">
    <turnGravityOff>true</turnGravityOff>
    <mu1>0.112</mu1>
    <mu2>0.112</mu2>
    <kp>1000000</kp>
    <kd>1</kd>
    <selfCollide>true</selfCollide>
    <maxVel>0.01</maxVel>
    <minDepth>0.003</minDepth>
  </gazebo>
  <!-- joint 1: tool_yaw -->
  <joint name="right_tool_pitch" type="revolute">
    <parent link="right_tool_base_link"/>
    <child link="right_tool_pitch_link"/>
    <axis xyz="0 0 1"/>
    <origin rpy="0 -1.57079632679 3.14159265359" xyz="0.0 0.0 0.0"/>
    <limit effort="1000" lower="-1.5707" upper="1.5707" velocity="3"/>
  </joint>
  <!-- joint 2: tool_pitch -->
  <joint name="right_tool_roll" type="revolute">
    <parent link="right_tool_pitch_link"/>
    <child link="right_tool_roll_link"/>
    <axis xyz="0 0 1"/>
    <origin rpy="-1.57079632679 -1.57079632679 0" xyz="0 0 0"/>
    <limit effort="1000" lower="-1.5707" upper="1.5707" velocity="3"/>
  </joint>
  <!-- joint : tool Roll -->
  <joint name="right_tool_yaw" type="revolute">
    <parent link="right_tool_roll_link"/>
    <child link="right_tool_yaw_link"/>
    <axis xyz="0 0 1"/>
    <origin rpy="1.57079632679 0 0" xyz="0 0 0"/>
    <limit effort="1000" lower="-4.71238898038" upper="4.71238898038" velocity="3"/>
  </joint>
  <!-- joint 3: insertion -->
  <joint name="right_tool_insertion" type="prismatic">
    <parent link="right_tool_yaw_link"/>
    <child link="right_tool_main_link"/>
    <axis xyz="0 0 1"/>
    <origin rpy="0 0 0" xyz="0 0 -0.3908"/>
    <limit effort="1000" lower="0.0" upper="0.240" velocity="3"/>
  </joint>
  <joint name="right_tool_wrist_fixed" type="fixed">
    <parent link="right_tool_main_link"/>
    <child link="right_tool_wrist_link"/>
    <axis xyz="0 0 1"/>
    <origin rpy="0 0 0" xyz="0 0 0.3752"/>
  </joint>
  <!-- joint 4-1: tool roll shaft joint FIXED-->
  <joint name="right_tool_wrist_shaft_fixed" type="fixed">
    <parent link="right_tool_wrist_link"/>
    <child link="right_tool_wrist_shaft_link"/>
    <axis xyz="0 0 1"/>
    <origin rpy="0 0 0" xyz="0 0 0.0"/>
  </joint>
  <transmission name="right_tool_pitch_trans">
    <type>transmission_interface/SimpleTransmission</type>
    <joint name="right_tool_pitch">
      <hardwareInterface>hardware_interface/PositionJointInterface</hardwareInterface>
    </joint>
    <actuator name="right_tool_pitch_motor">
      <hardwareInterface>hardware_interface/PositionJointInterface</hardwareInterface>
      <mechanicalReduction>1</mechanicalReduction>
    </actuator>
  </transmission>
  <transmission name="right_tool_roll_trans">
    <type>transmission_interface/SimpleTransmission</type>
    <joint name="right_tool_roll">
      <hardwareInterface>hardware_interface/PositionJointInterface</hardwareInterface>
    </joint>
    <actuator name="right_tool_roll_motor">
      <hardwareInterface>hardware_interface/PositionJointInterface</hardwareInterface>
      <mechanicalReduction>1</mechanicalReduction>
    </actuator>
  </transmission>
  <transmission name="right_tool_yaw_trans">
    <type>transmission_interface/SimpleTransmission</type>
    <joint name="right_tool_yaw">
      <hardwareInterface>hardware_interface/PositionJointInterface</hardwareInterface>
    </joint>
    <actuator name="right_tool_yaw_motor">
      <hardwareInterface>hardware_interface/PositionJointInterface</hardwareInterface>
      <mechanicalReduction>1</mechanicalReduction>
    </actuator>
  </transmission>
  <transmission name="right_tool_insertion_trans">
    <type>transmission_interface/SimpleTransmission</type>
    <joint name="right_tool_insertion">
      <hardwareInterface>hardware_interface/PositionJointInterface</hardwareInterface>
    </joint>
    <actuator name="right_tool_insertion_motor">
      <hardwareInterface>hardware_interface/PositionJointInterface</hardwareInterface>
      <mechanicalReduction>1</mechanicalReduction>
    </actuator>
  </transmission>
  <gazebo reference="right_tool_pitch">
    <!-- <implicitSpringDamper>0</implicitSpringDamper>
			<provideFeedback>1</provideFeedback> -->
  </gazebo>
  <gazebo reference="right_tool_roll">
    <!-- <implicitSpringDamper>0</implicitSpringDamper>
			<provideFeedback>1</provideFeedback> -->
  </gazebo>
  <gazebo reference="right_tool_yaw">
    <!-- <implicitSpringDamper>0</implicitSpringDamper>
			<provideFeedback>1</provideFeedback> -->
  </gazebo>
  <gazebo reference="right_tool_insertion">
    <!-- <implicitSpringDamper>0</implicitSpringDamper>
			<provideFeedback>1</provideFeedback> -->
  </gazebo>
  <gazebo reference="right_tool_wrist_fixed">
    <!-- <implicitSpringDamper>0</implicitSpringDamper>
			<provideFeedback>1</provideFeedback> -->
  </gazebo>
  <gazebo reference="right_tool_wrist_shaft_fixed">
    <!-- <implicitSpringDamper>0</implicitSpringDamper>
			<provideFeedback>1</provideFeedback> -->
  </gazebo>
  <!-- link 5: tool_wrist_forceps_link -->
  <link name="right_tool_wrist_forceps_link">
    <visual>
      <origin rpy="0.00 -1.5708 0.0" xyz="-0.0024 0.00 0.000"/>
      <geometry>
        <mesh filename="package://surgical_sim/models/meshes/stl/tool/tool_wrist_forceps_link_1.stl"/>
      </geometry>
      <material name="gray">
        <color rgba="0.5 0.5 0.9 1.0"/>
      </material>
    </visual>
    <collision>
      <origin rpy="0.00 -1.5708 0.0" xyz="-0.0024 0.00 0.000"/>
      <geometry>
        <mesh filename="package://surgical_sim/models/meshes/stl/tool/tool_wrist_forceps_link_1.stl"/>
      </geometry>
    </collision>
    <inertial>
      <origin rpy="0 0 0" xyz="0 0 0"/>
      <mass value="0.1"/>
      <inertia ixx="1" ixy="0.0" ixz="0.0" iyy="1" iyz="0.0" izz="0.05"/>
    </inertial>
  </link>
  <!-- link 6: tool_wrist_forceps_link_shaft -->
  <link name="right_tool_wrist_forceps_link_shaft">
    <visual>
      <origin rpy="0.00 1.5708 0.0" xyz="0.0 -0.0002 0.000"/>
      <geometry>
        <mesh filename="package://surgical_sim/models/meshes/stl/tool/tool_wrist_forceps_link_1_shaft.stl"/>
      </geometry>
      <material name="gray">
        <color rgba="0.5 0.5 0.9 1.0"/>
      </material>
    </visual>
    <collision>
      <origin rpy="0.00 1.5708 0.0" xyz="0.0 0.00 0.000"/>
      <geometry>
        <mesh filename="package://surgical_sim/models/meshes/stl/tool/tool_wrist_forceps_link_1_shaft.stl"/>
      </geometry>
    </collision>
    <inertial>
      <origin rpy="0 0 0" xyz="0 0 0"/>
      <mass value="0.1"/>
      <inertia ixx="1" ixy="0.0" ixz="0.0" iyy="1" iyz="0.0" izz="0.05"/>
    </inertial>
  </link>
  <!-- link 6-1: Outer open angle link 1 -->
  <link name="right_tool_wrist_forceps_link_2_left">
    <visual>
      <origin rpy="0.0 0 0.0" xyz="0 0 0.00195"/>
      <geometry>
        <mesh filename="package://surgical_sim/models/meshes/stl/tool/tool_wrist_forceps_link_2_left.stl"/>
      </geometry>
    </visual>
    <collision>
      <origin rpy="0.0 0 0.0" xyz="0 0 0.00195"/>
      <geometry>
        <mesh filename="package://surgical_sim/models/meshes/stl/tool/tool_wrist_forceps_link_2_left.stl"/>
      </geometry>
    </collision>
    <inertial>
      <origin rpy="0 0 0" xyz="0 0 0"/>
      <mass value="0.1"/>
      <inertia ixx="1" ixy="0.0" ixz="0.0" iyy="1" iyz="0.0" izz="0.05"/>
    </inertial>
  </link>
  <!-- link 6-2: Outer open angle link 2 -->
  <link name="right_tool_wrist_forceps_link_2_right">
    <visual>
      <origin rpy="0 0 -3.1415926" xyz="0 0 0.00195"/>
      <geometry>
        <mesh filename="package://surgical_sim/models/meshes/stl/tool/tool_wrist_forceps_link_2_right.stl"/>
      </geometry>
    </visual>
    <collision>
      <origin rpy="0 0 -3.1415926" xyz="0 0 0.00195"/>
      <geometry>
        <mesh filename="package://surgical_sim/models/meshes/stl/tool/tool_wrist_forceps_link_2_right.stl"/>
      </geometry>
    </collision>
    <inertial>
      <origin rpy="0 0 0" xyz="0 0 0"/>
      <mass value="0.1"/>
      <inertia ixx="1" ixy="0.0" ixz="0.0" iyy="1" iyz="0.0" izz="0.05"/>
    </inertial>
  </link>
  <link name="right_tool_tip_link"/>
  <link name="right_tool_tip_link_ee"/>
  <gazebo reference="right_tool_wrist_forceps_link">
    <turnGravityOff>true</turnGravityOff>
    <mu1>0.112</mu1>
    <mu2>0.112</mu2>
    <kp>1000000</kp>
    <kd>1</kd>
    <selfCollide>true</selfCollide>
    <maxVel>0.01</maxVel>
    <minDepth>0.003</minDepth>
  </gazebo>
  <gazebo reference="right_tool_wrist_forceps_link_shaft">
    <turnGravityOff>true</turnGravityOff>
    <mu1>0.112</mu1>
    <mu2>0.112</mu2>
    <kp>1000000</kp>
    <kd>1</kd>
    <selfCollide>true</selfCollide>
    <maxVel>0.01</maxVel>
    <minDepth>0.003</minDepth>
  </gazebo>
  <gazebo reference="right_tool_wrist_forceps_link_2_left">
    <turnGravityOff>true</turnGravityOff>
    <mu1>0.112</mu1>
    <mu2>0.112</mu2>
    <kp>1000000</kp>
    <kd>1</kd>
    <selfCollide>true</selfCollide>
    <maxVel>0.01</maxVel>
    <minDepth>0.003</minDepth>
  </gazebo>
  <gazebo reference="right_tool_wrist_forceps_link_2_right">
    <turnGravityOff>true</turnGravityOff>
    <mu1>0.112</mu1>
    <mu2>0.112</mu2>
    <kp>1000000</kp>
    <kd>1</kd>
    <selfCollide>true</selfCollide>
    <maxVel>0.01</maxVel>
    <minDepth>0.003</minDepth>
  </gazebo>
  <gazebo reference="right_tool_tip_link">
    <turnGravityOff>true</turnGravityOff>
    <mu1>0.112</mu1>
    <mu2>0.112</mu2>
    <kp>1000000</kp>
    <kd>1</kd>
    <selfCollide>true</selfCollide>
    <maxVel>0.01</maxVel>
    <minDepth>0.003</minDepth>
  </gazebo>
  <gazebo reference="right_tool_tip_link_ee">
    <turnGravityOff>true</turnGravityOff>
    <mu1>0.112</mu1>
    <mu2>0.112</mu2>
    <kp>1000000</kp>
    <kd>1</kd>
    <selfCollide>true</selfCollide>
    <maxVel>0.01</maxVel>
    <minDepth>0.003</minDepth>
  </gazebo>
  <!-- joint 5: tool wrist pitch joint -->
  <joint name="right_tool_wrist_pitch" type="revolute">
    <parent link="right_tool_wrist_shaft_link"/>
    <!-- <parent link="${tool_id}_world"/> -->
    <child link="right_tool_wrist_forceps_link"/>
    <axis xyz="0 0 1"/>
    <origin rpy="-1.5708 -1.5708 3.14159265359" xyz="0 0 0"/>
    <limit effort="1000" lower="-1.57079632679" upper="1.57079632679" velocity="3.0"/>
  </joint>
  <!-- joint 6: Tool wrist yaw joint -->
  <joint name="right_tool_wrist_yaw" type="revolute">
    <parent link="right_tool_wrist_forceps_link"/>
    <child link="right_tool_wrist_forceps_link_shaft"/>
    <axis xyz="0 0 1"/>
    <origin rpy="0.00 -1.5708 -1.5708" xyz="0.0091 0 0"/>
    <limit effort="1000" lower="-1.57079632679" upper="1.57079632679" velocity="3.0"/>
  </joint>
  <!-- joint 6-1: tool open angle 1 -->
  <joint name="right_tool_wrist_open_angle" type="revolute">
    <parent link="right_tool_wrist_forceps_link_shaft"/>
    <child link="right_tool_wrist_forceps_link_2_left"/>
    <axis xyz="0 0 1"/>
    <origin rpy="0 0 0" xyz="0 0 0"/>
    <limit effort="1000" lower="0" upper="0.523598775598" velocity="3.0"/>
  </joint>
  <!-- joint 6-2: tool open angle 2  -->
  <joint name="right_tool_wrist_open_angle_mimic" type="revolute">
    <parent link="right_tool_wrist_forceps_link_shaft"/>
    <child link="right_tool_wrist_forceps_link_2_right"/>
    <axis xyz="0 0 1"/>
    <origin rpy="3.1415926 0 0" xyz="0 0 0"/>
    <limit effort="1000" lower="0" upper="0.523598775598" velocity="3.0"/>
    <mimic joint="right_tool_wrist_open_angle" multiplier="1"/>
  </joint>
  <!-- tool tip -->
  <joint name="right_tool_tip_" type="fixed">
    <parent link="right_tool_wrist_forceps_link_shaft"/>
    <child link="right_tool_tip_link"/>
    <origin rpy="0 1.57079632679 1.57079632679" xyz="0 0.0202 0"/>
  </joint>
  <joint name="right_tool_tip_ee" type="fixed">
    <parent link="right_tool_tip_link"/>
    <child link="right_tool_tip_link_ee"/>
    <origin rpy="3.14159265359 0 -1.57079632679" xyz="0 0 0"/>
  </joint>
  <transmission name="right_tool_wrist_pitch_trans">
    <type>transmission_interface/SimpleTransmission</type>
    <joint name="right_tool_wrist_pitch">
      <hardwareInterface>hardware_interface/PositionJointInterface</hardwareInterface>
    </joint>
    <actuator name="right_tool_wrist_pitch_motor">
      <hardwareInterface>hardware_interface/PositionJointInterface</hardwareInterface>
      <mechanicalReduction>1</mechanicalReduction>
    </actuator>
  </transmission>
  <transmission name="right_tool_wrist_yaw_trans">
    <type>transmission_interface/SimpleTransmission</type>
    <joint name="right_tool_wrist_yaw">
      <hardwareInterface>hardware_interface/PositionJointInterface</hardwareInterface>
    </joint>
    <actuator name="right_tool_wrist_yaw_motor">
      <hardwareInterface>hardware_interface/PositionJointInterface</hardwareInterface>
      <mechanicalReduction>1</mechanicalReduction>
    </actuator>
  </transmission>
  <transmission name="right_tool_wrist_open_angle_trans">
    <type>transmission_interface/SimpleTransmission</type>
    <joint name="right_tool_wrist_open_angle">
      <hardwareInterface>hardware_interface/PositionJointInterface</hardwareInterface>
    </joint>
    <actuator name="right_tool_wrist_open_angle_motor">
      <hardwareInterface>hardware_interface/PositionJointInterface</hardwareInterface>
      <mechanicalReduction>1</mechanicalReduction>
    </actuator>
  </transmission>
  <transmission name="right_tool_wrist_open_angle_mimic_trans">
    <type>transmission_interface/SimpleTransmission</type>
    <joint name="right_tool_wrist_open_angle_mimic">
      <hardwareInterface>hardware_interface/PositionJointInterface</hardwareInterface>
    </joint>
    <actuator name="right_tool_wrist_open_angle_mimic_motor">
      <hardwareInterface>hardware_interface/PositionJointInterface</hardwareInterface>
      <mechanicalReduction>1</mechanicalReduction>
    </actuator>
  </transmission>
  <gazebo reference="right_tool_wrist_pitch">
    <!-- <implicitSpringDamper>0</implicitSpringDamper>
			<provideFeedback>1</provideFeedback> -->
  </gazebo>
  <gazebo reference="right_tool_wrist_yaw">
    <!-- <implicitSpringDamper>0</implicitSpringDamper>
			<provideFeedback>1</provideFeedback> -->
  </gazebo>
  <gazebo reference="right_tool_wrist_open_angle">
    <!-- <implicitSpringDamper>0</implicitSpringDamper>
			<provideFeedback>1</provideFeedback> -->
  </gazebo>
  <gazebo reference="right_tool_wrist_open_angle_mimic">
    <!-- <implicitSpringDamper>0</implicitSpringDamper>
			<provideFeedback>1</provideFeedback> -->
  </gazebo>
  <gazebo reference="right_tool_tip_">
    <!-- <implicitSpringDamper>0</implicitSpringDamper>
			<provideFeedback>1</provideFeedback> -->
  </gazebo>
  <gazebo reference="right_tool_tip_ee">
    <!-- <implicitSpringDamper>0</implicitSpringDamper>
			<provideFeedback>1</provideFeedback> -->
  </gazebo>
  <joint name="world_fixed" type="fixed">
    <parent link="world"/>
    <child link="right_tool_base_link"/>
    <origin rpy="0 0 0" xyz="0.015 0.515 1.3"/>
  </joint>
  <gazebo reference="right_tool_base_link">
    <turnGravityOff>true</turnGravityOff>
    <mu1>0.112</mu1>
    <mu2>0.112</mu2>
    <kp>1000000</kp>
    <kd>1</kd>
    <selfCollide>true</selfCollide>
    <maxVel>0.01</maxVel>
    <minDepth>0.003</minDepth>
  </gazebo>
  <gazebo>
    <plugin filename="libgazebo_ros_control.so" name="gazebo_ros_control">
      <robotNamespace>right_tool</robotNamespace>
      <robotParam>/right_tool/robot_description</robotParam>
      <robotSimType>gazebo_ros_control/DefaultRobotHWSim</robotSimType>
      <legacyModeNS>false</legacyModeNS>
    </plugin>
  </gazebo>
</robot>

