<?xml version="1.0" ?>
<!-- =================================================================================== -->
<!-- |    This document was autogenerated by xacro from leg.create.xacro               | -->
<!-- |    EDITING THIS FILE BY HAND IS NOT RECOMMENDED                                 | -->
<!-- =================================================================================== -->
<robot name="leg_as_robot" xmlns:xacro="http://www.ros.org/wiki/xacro">
  <!--[kg] -->
  <!-- r8_leg_foot_tip [m]-->
  <!-- [m]-->
  <!-- [m]-->
  <link name="virtual_platform_base_link"/>
  <link name="hip_base_link">
    <visual>
      <origin rpy="0 0 0" xyz="0 0 0"/>
      <geometry>
        <mesh filename="package://leg_as_robot/model/meshes/dae/leg_base_visual.dae"/>
      </geometry>
    </visual>
    <collision>
      <origin rpy="0 0 0" xyz="0 0 0"/>
      <geometry>
        <mesh filename="package://leg_as_robot/model/meshes/stl/leg_base_collision.stl"/>
      </geometry>
    </collision>
  </link>
  <link name="hip_adduction_link"/>
  <!-- virtual link-->
  <link name="hip_extension_link"/>
  <!-- virtual link-->
  <link name="hip_roll_link">
    <inertial>
      <origin rpy="0 0 0" xyz="0.00265863 -0.00827375 0.17215567"/>
      <mass value="12.0101"/>
      <!-- kg -->
      <inertia ixx="0.25495934" ixy="0.00092859" ixz="-0.00803351" iyy="0.25972836" iyz="0.00151866" izz="0.05431793"/>
    </inertial>
    <visual>
      <origin rpy="0 0 0" xyz="0 0 0"/>
      <geometry>
        <mesh filename="package://leg_as_robot/model/meshes/dae/thigh_visual.dae"/>
      </geometry>
    </visual>
    <collision>
      <origin rpy="0 0 0" xyz="0 0 0"/>
      <geometry>
        <mesh filename="package://leg_as_robot/model/meshes/stl/thigh_collision.stl"/>
      </geometry>
    </collision>
  </link>
  <link name="knee_extension_link">
    <inertial>
      <origin rpy="0 0 0" xyz="0.14893265 0.01010783 -0.00938572"/>
      <mass value="3.7931"/>
      <!-- kg -->
      <inertia ixx="0.00474593" ixy="0.00116322" ixz="0.00035670" iyy="0.04707968" iyz="0.00006150" izz="0.04724374"/>
    </inertial>
    <visual>
      <origin rpy="0 0 0" xyz="0 0 0"/>
      <geometry>
        <mesh filename="package://leg_as_robot/model/meshes/dae/shin_visual.dae"/>
      </geometry>
    </visual>
    <collision>
      <origin rpy="0 0 0" xyz="0 0 0"/>
      <geometry>
        <mesh filename="package://leg_as_robot/model/meshes/stl/shin_collision.stl"/>
      </geometry>
    </collision>
  </link>
  <link name="ankle_pitch_link"/>
  <!-- virtual link-->
  <link name="ankle_roll_link"/>
  <!-- virtual link-->
  <link name="ankle_yaw_link">
    <inertial>
      <origin rpy="0 0 0" xyz="-0.00089807 -0.04499748 -0.04201224"/>
      <mass value="1.1039"/>
      <!-- kg -->
      <inertia ixx="0.00322038" ixy="-0.00005516" ixz="0.00007652" iyy="0.00084882" iyz="0.00056936" izz="0.00297569"/>
    </inertial>
    <visual>
      <origin rpy="0 0 0" xyz="0 0 0"/>
      <geometry>
        <mesh filename="package://leg_as_robot/model/meshes/dae/foot_visual.dae"/>
      </geometry>
    </visual>
    <collision>
      <origin rpy="0 0 0" xyz="0 0 0"/>
      <geometry>
        <mesh filename="package://leg_as_robot/model/meshes/stl/foot_collision.stl"/>
      </geometry>
    </collision>
  </link>
  <link name="foot_base"/>
  <link name="foot_tip"/>
  <link name="virtual_pedal_tip"/>
  <joint name="hip_fixed" type="fixed">
    <origin rpy="0 0 0" xyz="0 -0.47046 0.9246"/>
    <!-- <origin xyz="0 -0.5100 0.9246" rpy="0 0 0"/> -->
    <parent link="virtual_platform_base_link"/>
    <child link="hip_base_link"/>
  </joint>
  <joint name="hip_adduction" type="revolute">
    <origin rpy="0 0 0" xyz="0 0 0"/>
    <parent link="hip_base_link"/>
    <child link="hip_adduction_link"/>
    <limit effort="30" lower="-0.767944870878" upper="0.0" velocity="10.0"/>
    <axis xyz="0 0 1"/>
  </joint>
  <joint name="hip_extension" type="revolute">
    <origin rpy="1.57079632679 0 1.57079632679" xyz="0 0 0"/>
    <parent link="hip_adduction_link"/>
    <child link="hip_extension_link"/>
    <limit effort="30" lower="-0.0872664625997" upper="0.558505360638" velocity="10.0"/>
    <axis xyz="0 0 1"/>
  </joint>
  <joint name="hip_roll" type="revolute">
    <origin rpy="1.57079632679 0 1.57079632679" xyz="0 0 0"/>
    <parent link="hip_extension_link"/>
    <child link="hip_roll_link"/>
    <limit effort="30" lower="-0.575958653158" upper="0.575958653158" velocity="10.0"/>
    <axis xyz="0 0 1"/>
  </joint>
  <joint name="knee_extension" type="revolute">
    <origin rpy="-1.57079632679 0 3.14159265359" xyz="0 0 0.43"/>
    <parent link="hip_roll_link"/>
    <child link="knee_extension_link"/>
    <limit effort="30" lower="-1.57079632679" upper="0.523598775598" velocity="10.0"/>
    <axis xyz="0 0 1"/>
  </joint>
  <joint name="ankle_pitch" type="revolute">
    <origin rpy="3.14159265359 0 3.14159265359" xyz="0.38 0 0"/>
    <parent link="knee_extension_link"/>
    <child link="ankle_pitch_link"/>
    <limit effort="30" lower="-0.799360797413" upper="0.520108117094" velocity="10.0"/>
    <axis xyz="0 0 1"/>
  </joint>
  <joint name="ankle_roll" type="revolute">
    <origin rpy="1.57079632679 0 0" xyz="0 0 0"/>
    <parent link="ankle_pitch_link"/>
    <child link="ankle_roll_link"/>
    <limit effort="30" lower="-0.296705972839" upper="0.383972435439" velocity="10.0"/>
    <axis xyz="0 0 1"/>
  </joint>
  <joint name="ankle_yaw" type="revolute">
    <origin rpy="-1.57079632679 0 -1.57079632679" xyz="0 0 0"/>
    <parent link="ankle_roll_link"/>
    <child link="ankle_yaw_link"/>
    <limit effort="30" lower="-0.452040276267" upper="0.628318530718" velocity="10.0"/>
    <axis xyz="0 0 1"/>
  </joint>
  <joint name="fixed_foot_base" type="fixed">
    <origin rpy="0 0 -1.57079632679" xyz="0 -0.04046 -0.08"/>
    <parent link="ankle_yaw_link"/>
    <child link="foot_base"/>
  </joint>
  <joint name="fixed_foot_tip" type="fixed">
    <origin rpy="0 0 0" xyz="0.15621 0 0"/>
    <parent link="foot_base"/>
    <child link="foot_tip"/>
  </joint>
  <joint name="fixed_pedal_tip" type="fixed">
    <origin rpy="0 0 0" xyz="0.05279 0 0"/>
    <parent link="foot_tip"/>
    <child link="virtual_pedal_tip"/>
  </joint>
</robot>
