<?xml version="1.0" ?>
<!-- =================================================================================== -->
<!-- |    This document was autogenerated by xacro from target_object.urdf.xacro       | -->
<!-- |    EDITING THIS FILE BY HAND IS NOT RECOMMENDED                                 | -->
<!-- =================================================================================== -->
<robot name="target_object" xmlns:xacro="http://www.ros.org/wiki/xacro">
  <link name="world"/>
  <link name="right_t1_target_base_link">
    <inertial>
      <origin rpy="0 0 0" xyz="0 0 0"/>
      <mass value="0.0001"/>
      <inertia ixx="1e-09" ixy="0.0" ixz="0.0" iyy="1e-09" iyz="0.0" izz="1e-09"/>
    </inertial>
  </link>
  <link name="right_t1_target_y_link">
    <inertial>
      <origin rpy="0 0 0" xyz="0 0 0"/>
      <mass value="0.0001"/>
      <inertia ixx="1e-09" ixy="0.0" ixz="0.0" iyy="1e-09" iyz="0.0" izz="1e-09"/>
    </inertial>
  </link>
  <link name="right_t1_target_z_link">
    <inertial>
      <origin rpy="0 0 0" xyz="0 0 0"/>
      <mass value="0.001"/>
      <inertia ixx="1e-08" ixy="0.0" ixz="0.0" iyy="1e-08" iyz="0.0" izz="1e-08"/>
    </inertial>
  </link>
  <link name="right_t1_target_main_link">
    <visual>
      <origin rpy="0 0 0" xyz="0 0 0"/>
      <geometry>
        <!-- <box size="${sphere_radius} ${2*sphere_radius} ${2*sphere_radius}"/> -->
        <!-- <sphere radius="${sphere_radius}"/> -->
        <mesh filename="package://surgical_sim/models/meshes/stl/target/target.STL"/>
      </geometry>
    </visual>
    <collision>
      <origin rpy="0 0 0" xyz="0 0 0"/>
      <geometry>
        <!-- <box size="${2*sphere_radius} ${2*sphere_radius} ${2*sphere_radius}"/> -->
        <!-- <sphere radius="${sphere_radius}"/> -->
        <mesh filename="package://surgical_sim/models/meshes/stl/target/target.STL"/>
      </geometry>
    </collision>
    <inertial>
      <origin rpy="0 0 0" xyz="-0.0027704 -0.00060187 -1.79059999999631E-08"/>
      <mass value="0.000037311"/>
      <inertia ixx="2.99391393770835E-08" ixy="-1.99518680567514E-09" ixz="2.72589485952597E-15" iyy="8.27991394391801E-09" iyz="3.38023650313121E-14" izz="3.77117809466761E-08"/>
    </inertial>
  </link>
  <joint name="right_t1_target_base_joint" type="fixed">
    <origin rpy="0.0 0 0" xyz="0.0 0.0 0.0"/>
    <parent link="world"/>
    <child link="right_t1_target_base_link"/>
  </joint>
  <joint name="right_t1_target_x_joint" type="prismatic">
    <origin rpy="0.0 0 0" xyz="0.0 0.0 0.0"/>
    <axis xyz="1.0 0.0 0.0"/>
    <parent link="right_t1_target_base_link"/>
    <child link="right_t1_target_y_link"/>
    <limit effort="1000.0" lower="-0.02" upper="0.02" velocity=".4"/>
  </joint>
  <joint name="right_t1_target_y_joint" type="prismatic">
    <origin rpy="0.0 0 0" xyz="0.0 0.0 0.0"/>
    <axis xyz="0.0 1.0 0.0"/>
    <parent link="right_t1_target_y_link"/>
    <child link="right_t1_target_z_link"/>
    <limit effort="1000.0" lower="-0.02" upper="0.02" velocity=".4"/>
  </joint>
  <joint name="right_t1_target_z_joint" type="prismatic">
    <origin rpy="0.0 0 0" xyz="0.0 0.0 0.0"/>
    <axis xyz="0.0 0.0 1.0"/>
    <parent link="right_t1_target_z_link"/>
    <child link="right_t1_target_main_link"/>
    <limit effort="1000.0" lower="-0.01" upper="0.04" velocity=".4"/>
  </joint>
  <gazebo reference="world">
    <turnGravityOff>false</turnGravityOff>
    <mu1>1000</mu1>
    <mu2>1000</mu2>
    <!-- <kp>${kpCollision}</kp> -->
    <!-- <kd>${kdCollision}</kd> -->
    <selfCollide>true</selfCollide>
    <!-- <maxVel>0.01</maxVel> -->
    <!-- <minDepth>0.003</minDepth-->
  </gazebo>
  <gazebo reference="right_t1_target_base_link">
    <turnGravityOff>false</turnGravityOff>
    <mu1>1000</mu1>
    <mu2>1000</mu2>
    <!-- <kp>${kpCollision}</kp> -->
    <!-- <kd>${kdCollision}</kd> -->
    <selfCollide>true</selfCollide>
    <!-- <maxVel>0.01</maxVel> -->
    <!-- <minDepth>0.003</minDepth-->
  </gazebo>
  <gazebo reference="right_t1_target_y_link">
    <turnGravityOff>false</turnGravityOff>
    <mu1>1000</mu1>
    <mu2>1000</mu2>
    <!-- <kp>${kpCollision}</kp> -->
    <!-- <kd>${kdCollision}</kd> -->
    <selfCollide>true</selfCollide>
    <!-- <maxVel>0.01</maxVel> -->
    <!-- <minDepth>0.003</minDepth-->
  </gazebo>
  <gazebo reference="right_t1_target_z_link">
    <turnGravityOff>false</turnGravityOff>
    <mu1>1000</mu1>
    <mu2>1000</mu2>
    <!-- <kp>${kpCollision}</kp> -->
    <!-- <kd>${kdCollision}</kd> -->
    <selfCollide>true</selfCollide>
    <!-- <maxVel>0.01</maxVel> -->
    <!-- <minDepth>0.003</minDepth-->
  </gazebo>
  <gazebo reference="right_t1_target_main_link">
    <turnGravityOff>false</turnGravityOff>
    <mu1>1000</mu1>
    <mu2>1000</mu2>
    <!-- <kp>${kpCollision}</kp> -->
    <!-- <kd>${kdCollision}</kd> -->
    <selfCollide>true</selfCollide>
    <!-- <maxVel>0.01</maxVel> -->
    <!-- <minDepth>0.003</minDepth-->
  </gazebo>
  <gazebo reference="right_t1_base_joint">
    <!-- <implicitSpringDamper>0</implicitSpringDamper>
			<provideFeedback>1</provideFeedback> -->
  </gazebo>
  <gazebo reference="right_t1_x_joint">
    <!-- <implicitSpringDamper>0</implicitSpringDamper>
			<provideFeedback>1</provideFeedback> -->
  </gazebo>
  <gazebo reference="right_t1_y_joint">
    <!-- <implicitSpringDamper>0</implicitSpringDamper>
			<provideFeedback>1</provideFeedback> -->
  </gazebo>
  <gazebo reference="right_t1_z_joint">
    <!-- <implicitSpringDamper>0</implicitSpringDamper>
			<provideFeedback>1</provideFeedback> -->
  </gazebo>
  <gazebo>
    <plugin filename="libgazebo_ros_control.so" name="gazebo_ros_control">
      <robotNamespace>/right_t1_target</robotNamespace>
      <robotSimType>gazebo_ros_control/DefaultRobotHWSim</robotSimType>
      <legacyModeNS>true</legacyModeNS>
    </plugin>
  </gazebo>
</robot>

