<sdf version='1.6'>
  <model name='target_object'>
    <link name='right_t1_target_base_link'>
      <pose frame=''>0 0 0 0 -0 0</pose>
      <inertial>
        <pose frame=''>0 0 0 0 -0 0</pose>
        <mass>0.0001</mass>
        <inertia>
          <ixx>1e-09</ixx>
          <ixy>0</ixy>
          <ixz>0</ixz>
          <iyy>1e-09</iyy>
          <iyz>0</iyz>
          <izz>1e-09</izz>
        </inertia>
      </inertial>
      <gravity>1</gravity>
      <velocity_decay/>
      <self_collide>1</self_collide>
    </link>
    <joint name='right_t1_target_base_joint' type='fixed'>
      <child>right_t1_target_base_link</child>
      <parent>world</parent>
    </joint>
    <link name='right_t1_target_y_link'>
      <pose frame=''>0 0 0 0 -0 0</pose>
      <inertial>
        <pose frame=''>0 0 0 0 -0 0</pose>
        <mass>0.0001</mass>
        <inertia>
          <ixx>1e-09</ixx>
          <ixy>0</ixy>
          <ixz>0</ixz>
          <iyy>1e-09</iyy>
          <iyz>0</iyz>
          <izz>1e-09</izz>
        </inertia>
      </inertial>
      <gravity>1</gravity>
      <velocity_decay/>
      <self_collide>1</self_collide>
    </link>
    <joint name='right_t1_target_x_joint' type='prismatic'>
      <child>right_t1_target_y_link</child>
      <parent>right_t1_target_base_link</parent>
      <axis>
        <xyz>1 0 0</xyz>
        <limit>
          <lower>-0.02</lower>
          <upper>0.02</upper>
          <effort>1000</effort>
          <velocity>0.4</velocity>
        </limit>
        <dynamics>
          <spring_reference>0</spring_reference>
          <spring_stiffness>0</spring_stiffness>
        </dynamics>
        <use_parent_model_frame>1</use_parent_model_frame>
      </axis>
    </joint>
    <link name='right_t1_target_z_link'>
      <pose frame=''>0 0 0 0 -0 0</pose>
      <inertial>
        <pose frame=''>0 0 0 0 -0 0</pose>
        <mass>0.001</mass>
        <inertia>
          <ixx>1e-08</ixx>
          <ixy>0</ixy>
          <ixz>0</ixz>
          <iyy>1e-08</iyy>
          <iyz>0</iyz>
          <izz>1e-08</izz>
        </inertia>
      </inertial>
      <gravity>1</gravity>
      <velocity_decay/>
      <self_collide>1</self_collide>
    </link>
    <joint name='right_t1_target_y_joint' type='prismatic'>
      <child>right_t1_target_z_link</child>
      <parent>right_t1_target_y_link</parent>
      <axis>
        <xyz>0 1 0</xyz>
        <limit>
          <lower>-0.02</lower>
          <upper>0.02</upper>
          <effort>1000</effort>
          <velocity>0.4</velocity>
        </limit>
        <dynamics>
          <spring_reference>0</spring_reference>
          <spring_stiffness>0</spring_stiffness>
        </dynamics>
        <use_parent_model_frame>1</use_parent_model_frame>
      </axis>
    </joint>
    <link name='right_t1_target_main_link'>
      <pose frame=''>0 0 0 0 -0 0</pose>
      <inertial>
        <pose frame=''>-0.00277 -0.000602 -0 0 -0 0</pose>
        <mass>3.7311e-05</mass>
        <inertia>
          <ixx>2.99391e-08</ixx>
          <ixy>-1.99519e-09</ixy>
          <ixz>2.72589e-15</ixz>
          <iyy>8.27991e-09</iyy>
          <iyz>3.38024e-14</iyz>
          <izz>3.77118e-08</izz>
        </inertia>
      </inertial>
      <collision name='right_t1_target_main_link_collision'>
        <pose frame=''>0 0 0 0 -0 0</pose>
        <geometry>
          <mesh>
            <scale>1 1 1</scale>
            <uri>model://surgical_sim/models/meshes/stl/target/target.STL</uri>
          </mesh>
        </geometry>
        <surface>
          <contact>
            <ode/>
          </contact>
          <friction>
            <ode>
              <mu>1000</mu>
              <mu2>1000</mu2>
            </ode>
          </friction>
        </surface>
      </collision>
      <visual name='right_t1_target_main_link_visual'>
        <pose frame=''>0 0 0 0 -0 0</pose>
        <geometry>
          <mesh>
            <scale>1 1 1</scale>
            <uri>model://surgical_sim/models/meshes/stl/target/target.STL</uri>
          </mesh>
        </geometry>
        <material>
          <script>
            <uri>__default__</uri>
            <name>__default__</name>
          </script>
        </material>
      </visual>
      <gravity>1</gravity>
      <velocity_decay/>
      <self_collide>1</self_collide>
    </link>
    <joint name='right_t1_target_z_joint' type='prismatic'>
      <child>right_t1_target_main_link</child>
      <parent>right_t1_target_z_link</parent>
      <axis>
        <xyz>0 0 1</xyz>
        <limit>
          <lower>-0.01</lower>
          <upper>0.04</upper>
          <effort>1000</effort>
          <velocity>0.4</velocity>
        </limit>
        <dynamics>
          <spring_reference>0</spring_reference>
          <spring_stiffness>0</spring_stiffness>
        </dynamics>
        <use_parent_model_frame>1</use_parent_model_frame>
      </axis>
    </joint>
    <static>0</static>
    <plugin name='gazebo_ros_control' filename='libgazebo_ros_control.so'>
      <robotNamespace>/right_t1_target</robotNamespace>
      <robotSimType>gazebo_ros_control/DefaultRobotHWSim</robotSimType>
      <legacyModeNS>true</legacyModeNS>
    </plugin>
  </model>
</sdf>
